Workbook

Sheet Dashboard
A1: Movie Industry ROI Analysis
A35: Analysis of 7,669 movies (5,000+ with valid budget and revenue data)
A36: Period: 1980-2020
A37: All revenues adjusted to 2023 dollars using CPI

Sheet Analysis
A2: Valid movie | B2: Yes
A4: Row Labels | B4: Average of Gross relative to budget
A5: G | B5: 3.5504056
A6: PG | B6: 3.1217287
A7: PG-13 | B7: 3.0216556
A8: R | B8: 2.40136
A9: NC-17 | B9: 1.5843237
A10: Grand Total | B10: 2.864802
A22: Valid movie | B22: Yes
A24: Row Labels | B24: Average of Gross relative to budget
A25: 8-9 | B25: 5.9867212
A26: 9-10 | B26: 4.9275759
A27: 7-8 | B27: 3.7524221
A28: 6-7 | B28: 2.5834207
A29: 5-6 | B29: 1.9381276
A30: 4-5 | B30: 1.7977551
A31: 3-4 | B31: 1.2591825
A32: 1-2 | B32: 1.1066367
A33: 2-3 | B33: 0.93170756
A34: Grand Total | B34: 2.8661203
A43: Valid movie | B43: Yes
A45: Row Labels | B45: Average of Gross relative to budget
A46: Family | B46: 10.143436
A47: Horror | B47: 4.2219441
A48: Mystery | B48: 3.6982681
A49: Animation | B49: 3.6833103
A50: Thriller | B50: 3.3342712
A51: Adventure | B51: 2.8997264
A52: Action | B52: 2.8727601
A53: Drama | B53: 2.5972081
A54: Comedy | B54: 2.5948028
A55: Biography | B55: 2.4134502
A56: Fantasy | B56: 2.3279211
A57: Crime | B57: 2.218839
... A61: Grand Total | B61: 2.8661203

Sheet Raw Movie Data
A1: name | B1: rating | C1: genre | D1: year | E1: released | F1: score | G1: votes | H1: director | I1: writer | J1: star | K1: country | L1: budget | M1: gross | N1: company | O1: runtime
A2: The Shining | B2: R | C2: Drama | D2: 1980 | E2: June 13, 1980 (United States) | F2: 8.4 | G2: 927000 | H2: Stanley Kubrick | I2: Stephen King | J2: Jack Nicholson | K2: United Kingdom | L2: 19000000 | M2: 46998772 | N2: Warner Bros. | O2: 146
A3: The Blue Lagoon | B3: R | C3: Adventure | D3: 1980 | E3: July 2, 1980 (United States) | F3: 5.8 | G3: 65000 | H3: Randal Kleiser | I3: Henry De Vere Stacpoole | J3: Brooke Shields | K3: United States | L3: 4500000 | M3: 58853106 | N3: Columbia Pictures | O3: 104
A4: Star Wars: Episode V - The Empire Strikes Back | B4: PG | C4: Action | D4: 1980 | E4: June 20, 1980 (United States) | F4: 8.7 | G4: 1200000 | H4: Irvin Kershner | I4: Leigh Brackett | J4: Mark Hamill | K4: United States | L4: 18000000 | M4: 538375067 | N4: Lucasfilm | O4: 124
A5: Airplane! | B5: PG | C5: Comedy | D5: 1980 | E5: July 2, 1980 (United States) | F5: 7.7 | G5: 221000 | H5: Jim Abrahams | I5: Jim Abrahams | J5: Robert Hays | K5: United States | L5: 3500000 | M5: 83453539 | N5: Paramount Pictures | O5: 88
A6: Caddyshack | B6: R | C6: Comedy | D6: 1980 | E6: July 25, 1980 (United States) | F6: 7.3 | G6: 108000 | H6: Harold Ramis | I6: Brian Doyle-Murray | J6: Chevy Chase | K6: United States | L6: 6000000 | M6: 39846344 | N6: Orion Pictures | O6: 98
A7: Friday the 13th | B7: R | C7: Horror | D7: 1980 | E7: May 9, 1980 (United States) | F7: 6.4 | G7: 123000 | H7: Sean S. Cunningham | I7: Victor Miller | J7: Betsy Palmer | K7: United States | L7: 550000 | M7: 39754601 | N7: Paramount Pictures | O7: 95
A8: The Blues Brothers | B8: R | C8: Action | D8: 1980 | E8: June 20, 1980 (United States) | F8: 7.9 | G8: 188000 | H8: John Landis | I8: Dan Aykroyd | J8: John Belushi | K8: United States | L8: 27000000 | M8: 115229890 | N8: Universal Pictures | O8: 133
A9: Raging Bull | B9: R | C9: Biography | D9: 1980 | E9: December 19, 1980 (United States) | F9: 8.2 | G9: 330000 | H9: Martin Scorsese | I9: Jake LaMotta | J9: Robert De Niro | K9: United States | L9: 18000000 | M9: 23402427 | N9: Chartoff-Winkler Productions | O9: 129
A10: Superman II | B10: PG | C10: Action | D10: 1980 | E10: June 19, 1981 (United States) | F10: 6.8 | G10: 101000 | H10: Richard Lester | I10: Jerry Siegel | J10: Gene Hackman | K10: United States | L10: 54000000 | M10: 108185706 | N10: Dovemead Films | O10: 127
A11: The Long Riders | B11: R | C11: Biography | D11: 1980 | E11: May 16, 1980 (United States) | F11: 7 | G11: 10000 | H11: Walter Hill | I11: Bill Bryden | J11: David Carradine | K11: United States | L11: 10000000 | M11: 15795189 | N11: United Artists | O11: 100
A12: Any Which Way You Can | B12: PG | C12: Action | D12: 1980 | E12: December 17, 1980 (United States) | F12: 6.1 | G12: 18000 | H12: Buddy Van Horn | I12: Stanford Sherman | J12: Clint Eastwood | K12: United States | L12: 15000000 | M12: 70687344 | N12: The Malpaso Company | O12: 116
A13: The Gods Must Be Crazy | B13: PG | C13: Adventure | D13: 1980 | E13: October 26, 1984 (United States) | F13: 7.3 | G13: 54000 | H13: Jamie Uys | I13: Jamie Uys | J13: N!xau | K13: South Africa | L13: 5000000 | M13: 30031783 | N13: C.A.T. Films | O13: 109
... A17: Somewhere in Time | B17: PG | C17: Drama | D17: 1980 | E17: October 3, 1980 (United States) | F17: 7.2 | G17: 27000 | H17: Jeannot Szwarc | I17: Richard Matheson | J17: Christopher Reeve | K17: United States | L17: 5100000 | M17: 9709597 | N17: Rastar Pictures | O17: 103
A18: Fame | B18: R | C18: Drama | D18: 1980 | E18: May 16, 1980 (United States) | F18: 6.6 | G18: 21000 | H18: Alan Parker | I18: Christopher Gore | J18: Eddie Barth | K18: United States | M18: 21202829 | N18: Metro-Goldwyn-Mayer (MGM) | O18: 134
A19: 9 to 5 | B19: PG | C19: Comedy | D19: 1980 | E19: December 19, 1980 (United States) | F19: 6.9 | G19: 29000 | H19: Colin Higgins | I19: Patricia Resnick | J19: Jane Fonda | K19: United States | L19: 10000000 | M19: 103300686 | N19: IPC Films | O19: 109
A20: The Fog | B20: R | C20: Horror | D20: 1980 | E20: February 8, 1980 (United States) | F20: 6.8 | G20: 66000 | H20: John Carpenter | I20: John Carpenter | J20: Adrienne Barbeau | K20: United States | L20: 1000000 | M20: 21448782 | N20: AVCO Embassy Pictures | O20: 89
A21: Stir Crazy | B21: R | C21: Comedy | D21: 1980 | E21: December 12, 1980 (United States) | F21: 6.8 | G21: 26000 | H21: Sidney Poitier | I21: Bruce Jay Friedman | J21: Gene Wilder | K21: United States | M21: 101300000 | N21: Columbia Pictures | O21: 111
A22: Cruising | B22: R | C22: Crime | D22: 1980 | E22: February 15, 1980 (United States) | F22: 6.5 | G22: 20000 | H22: William Friedkin | I22: William Friedkin | J22: Al Pacino | K22: West Germany | L22: 11000000 | M22: 19814523 | N22: Lorimar Film Entertainment | O22: 102
A23: Heaven's Gate | B23: R | C23: Adventure | D23: 1980 | E23: April 24, 1981 (United States) | F23: 6.8 | G23: 14000 | H23: Michael Cimino | I23: Michael Cimino | J23: Kris Kristofferson | K23: United States | L23: 44000000 | M23: 3484523 | N23: Partisan Productions | O23: 219
A24: The Final Countdown | B24: PG | C24: Action | D24: 1980 | E24: August 1, 1980 (United States) | F24: 6.7 | G24: 22000 | H24: Don Taylor | I24: Thomas Hunter | J24: Kirk Douglas | K24: United States | L24: 12000000 | M24: 16647800 | N24: Bryna Productions | O24: 103
A25: Xanadu | B25: PG | C25: Fantasy | D25: 1980 | E25: August 8, 1980 (United States) | F25: 5.3 | G25: 12000 | H25: Robert Greenwald | I25: Richard Christian Danus | J25: Olivia Newton-John | K25: United States | L25: 20000000 | M25: 22762571 | N25: Universal Pictures | O25: 96
A26: Urban Cowboy | B26: PG | C26: Drama | D26: 1980 | E26: June 6, 1980 (United States) | F26: 6.4 | G26: 14000 | H26: James Bridges | I26: Aaron Latham | J26: John Travolta | K26: United States | M26: 46918287 | N26: Paramount Pictures | O26: 132
A27: Altered States | B27: R | C27: Horror | D27: 1980 | E27: December 25, 1980 (United States) | F27: 6.9 | G27: 33000 | H27: Ken Russell | I27: Paddy Chayefsky | J27: William Hurt | K27: United States | M27: 19853892 | N27: Warner Bros. | O27: 102
A28: Little Darlings | B28: R | C28: Comedy | D28: 1980 | E28: March 21, 1980 (United States) | F28: 6.5 | G28: 5100 | H28: Ron Maxwell | I28: Kimi Peck | J28: Tatum O'Neal | K28: United States | M28: 34326249 | N28: Stephen Friedman/Kings Road Productions | O28: 96
A29: Raise the Titanic | B29: PG | C29: Action | D29: 1980 | E29: August 1, 1980 (United States) | F29: 5 | G29: 4100 | H29: Jerry Jameson | I29: Adam Kennedy | J29: Jason Robards | K29: United Kingdom | L29: 36000000 | N29: ITC Films | O29: 115
A30: Brubaker | B30: R | C30: Crime | D30: 1980 | E30: June 20, 1980 (United States) | F30: 7.2 | G30: 17000 | H30: Stuart Rosenberg | I30: W.D. Richter | J30: Robert Redford | K30: United States | L30: 9000000 | M30: 37121708 | N30: Twentieth Century Fox | O30: 131
A31: American Gigolo | B31: R | C31: Crime | D31: 1980 | E31: February 1, 1980 (United States) | F31: 6.2 | G31: 22000 | H31: Paul Schrader | I31: Paul Schrader | J31: Richard Gere | K31: United States | L31: 4800000 | M31: 22743674 | N31: Paramount Pictures | O31: 117
A32: My Bodyguard | B32: PG | C32: Comedy | D32: 1980 | E32: September 26, 1980 (United States) | F32: 7.1 | G32: 8900 | H32: Tony Bill | I32: Alan Ormsby | J32: Chris Makepeace | K32: United States | M32: 22482952 | N32: Twentieth Century Fox | O32: 102
A33: Prom Night | B33: R | C33: Horror | D33: 1980 | E33: July 18, 1980 (United States) | F33: 5.4 | G33: 16000 | H33: Paul Lynch | I33: William Gray | J33: Leslie Nielsen | K33: Canada | M33: 14796236 | N33: Guardian Trust Company | O33: 92
A34: Smokey and the Bandit II | B34: PG | C34: Action | D34: 1980 | E34: August 15, 1980 (United States) | F34: 5.3 | G34: 15000 | H34: Hal Needham | I34: Hal Needham | J34: Burt Reynolds | K34: United States | M34: 66132626 | N34: Universal Pictures | O34: 100
A35: Cattle Annie and Little Britches | B35: PG | C35: Drama | D35: 1980 | E35: April 24, 1981 (United States) | F35: 6.1 | G35: 604 | H35: Lamont Johnson | I35: David Eyre | J35: Scott Glenn | K35: United States | L35: 5100000 | M35: 534816 | N35: Cattle Annie Productions | O35: 97
A36: Seems Like Old Times | B36: PG | C36: Comedy | D36: 1980 | E36: December 19, 1980 (United States) | F36: 6.7 | G36: 9100 | H36: Jay Sandrich | I36: Neil Simon | J36: Goldie Hawn | K36: United States | M36: 43995918 | N36: Rastar Films | O36: 102
A37: Private Benjamin | B37: R | C37: Comedy | D37: 1980 | E37: October 10, 1980 (United States) | F37: 6.2 | G37: 24000 | H37: Howard Zieff | I37: Nancy Meyers | J37: Goldie Hawn | K37: United States | L37: 10000000 | M37: 69847348 | N37: Warner Bros. | O37: 109
A38: The Hollywood Knights | B38: R | C38: Comedy | D38: 1980 | E38: May 30, 1980 (United States) | F38: 6.3 | G38: 4300 | H38: Floyd Mutrux | I38: Floyd Mutrux | J38: Tony Danza | K38: United States | L38: 4000000 | M38: 10000000 | N38: PolyGram Filmed Entertainment | O38: 91
A39: Motel Hell | B39: R | C39: Comedy | D39: 1980 | E39: October 24, 1980 (United States) | F39: 6 | G39: 11000 | H39: Kevin Connor | I39: Robert Jaffe | J39: Rory Calhoun | K39: United States | L39: 3000000 | M39: 6342668 | N39: Camp Hill | O39: 101
A40: The Jazz Singer | B40: PG | C40: Drama | D40: 1980 | E40: December 19, 1980 (United States) | F40: 5.9 | G40: 4000 | H40: Richard Fleischer | I40: Samson Raphaelson | J40: Laurence Olivier | K40: United States | M40: 27118000 | N40: EMI Films | O40: 115
A41: Coal Miner's Daughter | B41: PG | C41: Biography | D41: 1980 | E41: March 7, 1980 (United States) | F41: 7.5 | G41: 17000 | H41: Michael Apted | I41: Thomas Rickman | J41: Sissy Spacek | K41: United States | M41: 67182787 | N41: Universal Pictures | O41: 124
A42: The Watcher in the Woods | B42: PG | C42: Family | D42: 1980 | E42: October 9, 1981 (United States) | F42: 6.3 | G42: 5700 | H42: John Hough | I42: Brian Clemens | J42: Bette Davis | K42: United States | M42: 5000000 | N42: Walt Disney Productions | O42: 84
A43: Breaker Morant | B43: PG | C43: Drama | D43: 1980 | E43: July 3, 1980 (Australia) | F43: 7.9 | G43: 13000 | H43: Bruce Beresford | I43: Jonathan Hardy | J43: Edward Woodward | K43: Australia | N43: The South Australian Film Corporation | O43: 107
...

Sheet Working Data
A1: name | B1: rating | C1: genre | D1: year | E1: released | F1: score | G1: votes | H1: director | I1: writer | J1: star | K1: country | L1: budget | M1: gross | N1: company | O1: runtime | P1: CPI of Release Year | Q1: Gross Revenue in 2023 Dollars | R1: Valid movie
A2: Disaster Movie | B2: PG-13 | C2: Comedy | D2: 2008 | E2: August 29, 2008 (United States) | F2: 1.9 | G2: 88000 | H2: Jason Friedberg | I2: Jason Friedberg | J2: Carmen Electra | K2: United States | L2: 20000000 | M2: 34816824 | N2: Lionsgate | O2: 87 | P2: =_xlfn.XLOOKUP(D2,Consumer_Price_Index!A:A,Consumer_Price_Index!B:B) -> 215.3 | Q2: =IF(ISNUMBER(M2), M2*(Consumer_Price_Index!$B$45/(_xlfn.XLOOKUP('Working Data'!D5308,Consumer_Price_Index!A:A,Consumer_Price_Index!B:B))), "Missing") -> 59902238 | R2: =IF(AND(ISNUMBER(L2), L2>0, ISNUMBER(M2), M2>0), "Yes", "No") -> Yes
A3: Superbabies: Baby Geniuses 2 | B3: PG | C3: Comedy | D3: 2004 | E3: August 27, 2004 (United States) | F3: 1.9 | G3: 30000 | H3: Bob Clark | I3: Robert Grasmere | J3: Jon Voight | K3: Germany | L3: 20000000 | M3: 9448644 | N3: ApolloMedia Distribution | O3: 88 | P3: =_xlfn.XLOOKUP(D3,Consumer_Price_Index!A:A,Consumer_Price_Index!B:B) -> 188.9 | Q3: =IF(ISNUMBER(M3), M3*(Consumer_Price_Index!$B$45/(_xlfn.XLOOKUP('Working Data'!D4596,Consumer_Price_Index!A:A,Consumer_Price_Index!B:B))), "Missing") -> 11995841 | R3: =IF(AND(ISNUMBER(L3), L3>0, ISNUMBER(M3), M3>0), "Yes", "No") -> Yes
A4: The Hottie & the Nottie | B4: PG-13 | C4: Comedy | D4: 2008 | E4: February 21, 2008 (Russia) | F4: 1.9 | G4: 36000 | H4: Tom Putnam | I4: Heidi Ferrer | J4: Paris Hilton | K4: United States | M4: 1596232 | N4: Purple Pictures | O4: 91 | P4: =_xlfn.XLOOKUP(D4,Consumer_Price_Index!A:A,Consumer_Price_Index!B:B) -> 215.3 | Q4: =IF(ISNUMBER(M4), M4*(Consumer_Price_Index!$B$45/(_xlfn.XLOOKUP('Working Data'!D5356,Consumer_Price_Index!A:A,Consumer_Price_Index!B:B))), "Missing") -> 2412559 | R4: =IF(AND(ISNUMBER(L4), L4>0, ISNUMBER(M4), M4>0), "Yes", "No") -> No
A5: From Justin to Kelly | B5: PG | C5: Comedy | D5: 2003 | E5: June 20, 2003 (United States) | F5: 2.1 | G5: 25000 | H5: Robert Iscove | I5: Kim Fuller | J5: Kelly Clarkson | K5: United States | L5: 12000000 | M5: 4928883 | N5: 19 Entertainment | O5: 81 | P5: =_xlfn.XLOOKUP(D5,Consumer_Price_Index!A:A,Consumer_Price_Index!B:B) -> 184 | Q5: =IF(ISNUMBER(M5), M5*(Consumer_Price_Index!$B$45/(_xlfn.XLOOKUP('Working Data'!D4414,Consumer_Price_Index!A:A,Consumer_Price_Index!B:B))), "Missing") -> 9854531.8 | R5: =IF(AND(ISNUMBER(L5), L5>0, ISNUMBER(M5), M5>0), "Yes", "No") -> Yes
A6: House of the Dead | B6: R | C6: Action | D6: 2003 | E6: October 10, 2003 (United States) | F6: 2.1 | G6: 36000 | H6: Uwe Boll | I6: Mark A. Altman | J6: Jonathan Cherry | K6: Germany | L6: 12000000 | M6: 13818181 | N6: Boll Kino Beteiligungs GmbH & Co. KG | O6: 90 | P6: =_xlfn.XLOOKUP(D6,Consumer_Price_Index!A:A,Consumer_Price_Index!B:B) -> 184 | Q6: =IF(ISNUMBER(M6), M6*(Consumer_Price_Index!$B$45/(_xlfn.XLOOKUP('Working Data'!D4344,Consumer_Price_Index!A:A,Consumer_Price_Index!B:B))), "Missing") -> 19555967 | R6: =IF(AND(ISNUMBER(L6), L6>0, ISNUMBER(M6), M6>0), "Yes", "No") -> Yes
A7: Leonard Part 6 | B7: PG | C7: Action | D7: 1987 | E7: December 18, 1987 (United States) | F7: 2.2 | G7: 7900 | H7: Paul Weiland | I7: Jonathan Reynolds | J7: Bill Cosby | K7: United States | L7: 24000000 | M7: 4615255 | N7: Columbia Pictures | O7: 85 | P7: =_xlfn.XLOOKUP(D7,Consumer_Price_Index!A:A,Consumer_Price_Index!B:B) -> 113.6 | Q7: =IF(ISNUMBER(M7), M7*(Consumer_Price_Index!$B$45/(_xlfn.XLOOKUP('Working Data'!D1191,Consumer_Price_Index!A:A,Consumer_Price_Index!B:B))), "Missing") -> 12830914 | R7: =IF(AND(ISNUMBER(L7), L7>0, ISNUMBER(M7), M7>0), "Yes", "No") -> Yes
A8: Son of the Mask | B8: PG | C8: Comedy | D8: 2005 | E8: February 18, 2005 (United States) | F8: 2.2 | G8: 53000 | H8: Lawrence Guterman | I8: Lance Khazei | J8: Jamie Kennedy | K8: United States | L8: 84000000 | M8: 59981548 | N8: New Line Cinema | O8: 94 | P8: =_xlfn.XLOOKUP(D8,Consumer_Price_Index!A:A,Consumer_Price_Index!B:B) -> 195.3 | Q8: =IF(ISNUMBER(M8), M8*(Consumer_Price_Index!$B$45/(_xlfn.XLOOKUP('Working Data'!D4725,Consumer_Price_Index!A:A,Consumer_Price_Index!B:B))), "Missing") -> 72785256 | R8: =IF(AND(ISNUMBER(L8), L8>0, ISNUMBER(M8), M8>0), "Yes", "No") -> Yes
A9: Student of the Year 2 | B9: Not Rated | C9: Action | D9: 2019 | E9: May 10, 2019 (United States) | F9: 2.2 | G9: 18000 | H9: Punit Malhotra | I9: Arshad Sayed | J9: Tiger Shroff | K9: India | M9: 1635907 | N9: Fox STAR Studios | O9: 146 | P9: =_xlfn.XLOOKUP(D9,Consumer_Price_Index!A:A,Consumer_Price_Index!B:B) -> 255.7 | Q9: =IF(ISNUMBER(M9), M9*(Consumer_Price_Index!$B$45/(_xlfn.XLOOKUP('Working Data'!D7597,Consumer_Price_Index!A:A,Consumer_Price_Index!B:B))), "Missing") -> 2285469.3 | R9: =IF(AND(ISNUMBER(L9), L9>0, ISNUMBER(M9), M9>0), "Yes", "No") -> No
A10: Who's Your Caddy? | B10: PG-13 | C10: Comedy | D10: 2007 | E10: July 27, 2007 (United States) | F10: 2.2 | G10: 15000 | H10: Don Michael Paul | I10: Don Michael Paul | J10: Big Boi | K10: United States | L10: 7000000 | M10: 5713425 | N10: Ascendant Pictures | O10: 93 | P10: =_xlfn.XLOOKUP(D10,Consumer_Price_Index!A:A,Consumer_Price_Index!B:B) -> 207.3 | Q10: =IF(ISNUMBER(M10), M10*(Consumer_Price_Index!$B$45/(_xlfn.XLOOKUP('Working Data'!D5196,Consumer_Price_Index!A:A,Consumer_Price_Index!B:B))), "Missing") -> 6933017.1 | R10: =IF(AND(ISNUMBER(L10), L10>0, ISNUMBER(M10), M10>0), "Yes", "No") -> Yes
A11: Glitter | B11: PG-13 | C11: Drama | D11: 2001 | E11: September 21, 2001 (United States) | F11: 2.3 | G11: 22000 | H11: Vondie Curtis-Hall | I11: Cheryl L. West | J11: Mariah Carey | K11: United States | L11: 22000000 | M11: 5271666 | N11: Twentieth Century Fox | O11: 104 | P11: =_xlfn.XLOOKUP(D11,Consumer_Price_Index!A:A,Consumer_Price_Index!B:B) -> 177.1 | Q11: =IF(ISNUMBER(M11), M11*(Consumer_Price_Index!$B$45/(_xlfn.XLOOKUP('Working Data'!D4024,Consumer_Price_Index!A:A,Consumer_Price_Index!B:B))), "Missing") -> 7967642 | R11: =IF(AND(ISNUMBER(L11), L11>0, ISNUMBER(M11), M11>0), "Yes", "No") -> Yes
A12: Alone in the Dark | B12: R | C12: Action | D12: 2005 | E12: January 28, 2005 (United States) | F12: 2.4 | G12: 42000 | H12: Uwe Boll | I12: Elan Mastai | J12: Christian Slater | K12: Canada | L12: 20000000 | M12: 12693645 | N12: AITD Productions | O12: 96 | P12: =_xlfn.XLOOKUP(D12,Consumer_Price_Index!A:A,Consumer_Price_Index!B:B) -> 195.3 | Q12: =IF(ISNUMBER(M12), M12*(Consumer_Price_Index!$B$45/(_xlfn.XLOOKUP('Working Data'!D4804,Consumer_Price_Index!A:A,Consumer_Price_Index!B:B))), "Missing") -> 19185286 | R12: =IF(AND(ISNUMBER(L12), L12>0, ISNUMBER(M12), M12>0), "Yes", "No") -> Yes
A13: Epic Movie | B13: PG-13 | C13: Adventure | D13: 2007 | E13: January 26, 2007 (United States) | F13: 2.4 | G13: 103000 | H13: Jason Friedberg | I13: Jason Friedberg | J13: Kal Penn | K13: United States | L13: 20000000 | M13: 87238158 | N13: New Regency Productions | O13: 86 | P13: =_xlfn.XLOOKUP(D13,Consumer_Price_Index!A:A,Consumer_Price_Index!B:B) -> 207.3 | Q13: =IF(ISNUMBER(M13), M13*(Consumer_Price_Index!$B$45/(_xlfn.XLOOKUP('Working Data'!D5110,Consumer_Price_Index!A:A,Consumer_Price_Index!B:B))), "Missing") -> 1.1075611e+08 | R13: =IF(AND(ISNUMBER(L13), L13>0, ISNUMBER(M13), M13>0), "Yes", "No") -> Yes
A14: Battlefield Earth | B14: PG-13 | C14: Action | D14: 2000 | E14: May 12, 2000 (United States) | F14: 2.5 | G14: 77000 | H14: Roger Christian | I14: Corey Mandell | J14: John Travolta | K14: United States | L14: 73000000 | M14: 29725663 | N14: Warner Bros. | O14: 118 | P14: =_xlfn.XLOOKUP(D14,Consumer_Price_Index!A:A,Consumer_Price_Index!B:B) -> 172.2 | Q14: =IF(ISNUMBER(M14), M14*(Consumer_Price_Index!$B$45/(_xlfn.XLOOKUP('Working Data'!D3686,Consumer_Price_Index!A:A,Consumer_Price_Index!B:B))), "Missing") -> 84176668 | R14: =IF(AND(ISNUMBER(L14), L14>0, ISNUMBER(M14), M14>0), "Yes", "No") -> Yes
A15: Dragonball Evolution | B15: PG | C15: Action | D15: 2009 | E15: April 10, 2009 (United States) | F15: 2.5 | G15: 71000 | H15: James Wong | I15: Ben Ramsey | J15: Justin Chatwin | K15: United States | L15: 30000000 | M15: 55720772 | N15: Twentieth Century Fox | O15: 85 | P15: =_xlfn.XLOOKUP(D15,Consumer_Price_Index!A:A,Consumer_Price_Index!B:B) -> 214.5 | Q15: =IF(ISNUMBER(M15), M15*(Consumer_Price_Index!$B$45/(_xlfn.XLOOKUP('Working Data'!D5528,Consumer_Price_Index!A:A,Consumer_Price_Index!B:B))), "Missing") -> 1.2465579e+08 | R15: =IF(AND(ISNUMBER(L15), L15>0, ISNUMBER(M15), M15>0), "Yes", "No") -> Yes
A16: Gigli | B16: R | C16: Comedy | D16: 2003 | E16: August 1, 2003 (United States) | F16: 2.5 | G16: 46000 | H16: Martin Brest | I16: Martin Brest | J16: Ben Affleck | K16: United States | L16: 54000000 | M16: 7266209 | N16: Revolution Studios | O16: 121 | P16: =_xlfn.XLOOKUP(D16,Consumer_Price_Index!A:A,Consumer_Price_Index!B:B) -> 184 | Q16: =IF(ISNUMBER(M16), M16*(Consumer_Price_Index!$B$45/(_xlfn.XLOOKUP('Working Data'!D4328,Consumer_Price_Index!A:A,Consumer_Price_Index!B:B))), "Missing") -> 22943149 | R16: =IF(AND(ISNUMBER(L16), L16>0, ISNUMBER(M16), M16>0), "Yes", "No") -> Yes
A17: Lawnmower Man 2: Beyond Cyberspace | B17: PG-13 | C17: Action | D17: 1996 | E17: January 12, 1996 (United States) | F17: 2.5 | G17: 9000 | H17: Farhad Mann | I17: Farhad Mann | J17: Patrick Bergin | K17: United States | L17: 15000000 | M17: 2409225 | N17: New Line Cinema | O17: 93 | P17: =_xlfn.XLOOKUP(D17,Consumer_Price_Index!A:A,Consumer_Price_Index!B:B) -> 156.9 | Q17: =IF(ISNUMBER(M17), M17*(Consumer_Price_Index!$B$45/(_xlfn.XLOOKUP('Working Data'!D2997,Consumer_Price_Index!A:A,Consumer_Price_Index!B:B))), "Missing") -> 3058711.9 | R17: =IF(AND(ISNUMBER(L17), L17>0, ISNUMBER(M17), M17>0), "Yes", "No") -> Yes
A18: The Garbage Pail Kids Movie | B18: PG | C18: Adventure | D18: 1987 | E18: August 22, 1987 (United States) | F18: 2.6 | G18: 7600 | H18: Rod Amateau | I18: Linda Palmer | J18: Anthony Newley | K18: United States | L18: 1000000 | M18: 1576615 | N18: Atlantic Entertainment Group | O18: 100 | P18: =_xlfn.XLOOKUP(D18,Consumer_Price_Index!A:A,Consumer_Price_Index!B:B) -> 113.6 | Q18: =IF(ISNUMBER(M18), M18*(Consumer_Price_Index!$B$45/(_xlfn.XLOOKUP('Working Data'!D1127,Consumer_Price_Index!A:A,Consumer_Price_Index!B:B))), "Missing") -> 3675551.6 | R18: =IF(AND(ISNUMBER(L18), L18>0, ISNUMBER(M18), M18>0), "Yes", "No") -> Yes
A19: Baby Geniuses | B19: PG | C19: Comedy | D19: 1999 | E19: March 12, 1999 (United States) | F19: 2.7 | G19: 26000 | H19: Bob Clark | I19: Steven Paul | J19: Kathleen Turner | K19: United States | L19: 12000000 | M19: 36450736 | N19: Crystal Sky Worldwide | O19: 97 | P19: =_xlfn.XLOOKUP(D19,Consumer_Price_Index!A:A,Consumer_Price_Index!B:B) -> 166.6 | Q19: =IF(ISNUMBER(M19), M19*(Consumer_Price_Index!$B$45/(_xlfn.XLOOKUP('Working Data'!D3561,Consumer_Price_Index!A:A,Consumer_Price_Index!B:B))), "Missing") -> 61737294 | R19: =IF(AND(ISNUMBER(L19), L19>0, ISNUMBER(M19), M19>0), "Yes", "No") -> Yes
A20: Ed | B20: PG | C20: Comedy | D20: 1996 | E20: March 15, 1996 (United States) | F20: 2.7 | G20: 8200 | H20: Bill CouturiÃ© | I20: Ken Richards | J20: Matt LeBlanc | K20: United States | L20: 24000000 | M20: 4422380 | N20: Longview Entertainment | O20: 94 | P20: =_xlfn.XLOOKUP(D20,Consumer_Price_Index!A:A,Consumer_Price_Index!B:B) -> 156.9 | Q20: =IF(ISNUMBER(M20), M20*(Consumer_Price_Index!$B$45/(_xlfn.XLOOKUP('Working Data'!D3044,Consumer_Price_Index!A:A,Consumer_Price_Index!B:B))), "Missing") -> 10309864 | R20: =IF(AND(ISNUMBER(L20), L20>0, ISNUMBER(M20), M20>0), "Yes", "No") -> Yes
A21: Inchon | B21: PG | C21: Drama | D21: 1981 | E21: September 17, 1982 (United States) | F21: 2.7 | G21: 659 | H21: Terence Young | I21: Robin Moore | J21: Laurence Olivier | K21: South Korea | L21: 46000000 | M21: 5200986 | N21: One Way Productions | O21: 140 | P21: =_xlfn.XLOOKUP(D21,Consumer_Price_Index!A:A,Consumer_Price_Index!B:B) -> 90.9 | Q21: =IF(ISNUMBER(M21), M21*(Consumer_Price_Index!$B$45/(_xlfn.XLOOKUP('Working Data'!D192,Consumer_Price_Index!A:A,Consumer_Price_Index!B:B))), "Missing") -> 9512247.5 | R21: =IF(AND(ISNUMBER(L21), L21>0, ISNUMBER(M21), M21>0), "Yes", "No") -> Yes
A22: It's Pat: the Movie | B22: PG-13 | C22: Comedy | D22: 1994 | E22: November 25, 1994 (Brazil) | F22: 2.7 | G22: 9500 | H22: Adam Bernstein | I22: Julia Sweeney | J22: Julia Sweeney | K22: United States | M22: 60822 | N22: Touchstone Pictures | O22: 77 | P22: =_xlfn.XLOOKUP(D22,Consumer_Price_Index!A:A,Consumer_Price_Index!B:B) -> 148.2 | Q22: =IF(ISNUMBER(M22), M22*(Consumer_Price_Index!$B$45/(_xlfn.XLOOKUP('Working Data'!D2592,Consumer_Price_Index!A:A,Consumer_Price_Index!B:B))), "Missing") -> 172234.79 | R22: =IF(AND(ISNUMBER(L22), L22>0, ISNUMBER(M22), M22>0), "Yes", "No") -> No
A23: Plump Fiction | B23: R | C23: Comedy | D23: 1997 | E23: May 23, 1997 (Poland) | F23: 2.7 | G23: 3600 | H23: Bob Koherr | I23: Bob Koherr | J23: Tommy Davidson | K23: United States | M23: 71145 | N23: Plump Fiction LLC | O23: 82 | P23: =_xlfn.XLOOKUP(D23,Consumer_Price_Index!A:A,Consumer_Price_Index!B:B) -> 160.5 | Q23: =IF(ISNUMBER(M23), M23*(Consumer_Price_Index!$B$45/(_xlfn.XLOOKUP('Working Data'!D3219,Consumer_Price_Index!A:A,Consumer_Price_Index!B:B))), "Missing") -> 86331.667 | R23: =IF(AND(ISNUMBER(L23), L23>0, ISNUMBER(M23), M23>0), "Yes", "No") -> No
A24: Date Movie | B24: PG-13 | C24: Comedy | D24: 2006 | E24: February 17, 2006 (United States) | F24: 2.8 | G24: 58000 | H24: Aaron Seltzer | I24: Jason Friedberg | J24: Alyson Hannigan | K24: United States | L24: 20000000 | M24: 85749034 | N24: New Regency Productions | O24: 83 | P24: =_xlfn.XLOOKUP(D24,Consumer_Price_Index!A:A,Consumer_Price_Index!B:B) -> 201.6 | Q24: =IF(ISNUMBER(M24), M24*(Consumer_Price_Index!$B$45/(_xlfn.XLOOKUP('Working Data'!D4990,Consumer_Price_Index!A:A,Consumer_Price_Index!B:B))), "Missing") -> 2.7075369e+08 | R24: =IF(AND(ISNUMBER(L24), L24>0, ISNUMBER(M24), M24>0), "Yes", "No") -> Yes
A25: Meet the Spartans | B25: PG-13 | C25: Comedy | D25: 2008 | E25: January 25, 2008 (United States) | F25: 2.8 | G25: 103000 | H25: Jason Friedberg | I25: Jason Friedberg | J25: Sean Maguire | K25: United States | L25: 30000000 | M25: 85897593 | N25: New Regency Productions | O25: 87 | P25: =_xlfn.XLOOKUP(D25,Consumer_Price_Index!A:A,Consumer_Price_Index!B:B) -> 215.3 | Q25: =IF(ISNUMBER(M25), M25*(Consumer_Price_Index!$B$45/(_xlfn.XLOOKUP('Working Data'!D5367,Consumer_Price_Index!A:A,Consumer_Price_Index!B:B))), "Missing") -> 1.9216591e+08 | R25: =IF(AND(ISNUMBER(L25), L25>0, ISNUMBER(M25), M25>0), "Yes", "No") -> Yes
A26: BloodRayne | B26: R | C26: Action | D26: 2005 | E26: January 6, 2006 (United States) | F26: 2.9 | G26: 34000 | H26: Uwe Boll | I26: Guinevere Turner | J26: Kristanna Loken | K26: Germany | L26: 25000000 | M26: 3650275 | N26: Boll Kino Beteiligungs GmbH & Co. KG | O26: 95 | P26: =_xlfn.XLOOKUP(D26,Consumer_Price_Index!A:A,Consumer_Price_Index!B:B) -> 195.3 | Q26: =IF(ISNUMBER(M26), M26*(Consumer_Price_Index!$B$45/(_xlfn.XLOOKUP('Working Data'!D4777,Consumer_Price_Index!A:A,Consumer_Price_Index!B:B))), "Missing") -> 7088838.7 | R26: =IF(AND(ISNUMBER(L26), L26>0, ISNUMBER(M26), M26>0), "Yes", "No") -> Yes
A27: Cool as Ice | B27: PG | C27: Comedy | D27: 1991 | E27: October 18, 1991 (United States) | F27: 2.9 | G27: 9100 | H27: David Kellogg | I27: David Stenn | J27: Vanilla Ice | K27: United States | L27: 6000000 | M27: 1193062 | N27: Alive Films | O27: 91 | P27: =_xlfn.XLOOKUP(D27,Consumer_Price_Index!A:A,Consumer_Price_Index!B:B) -> 136.2 | Q27: =IF(ISNUMBER(M27), M27*(Consumer_Price_Index!$B$45/(_xlfn.XLOOKUP('Working Data'!D1931,Consumer_Price_Index!A:A,Consumer_Price_Index!B:B))), "Missing") -> 3072916.2 | R27: =IF(AND(ISNUMBER(L27), L27>0, ISNUMBER(M27), M27>0), "Yes", "No") -> Yes
A28: Scream | B28: R | C28: Horror | D28: 1981 | E28: January 1, 1981 (United States) | F28: 2.9 | G28: 674 | H28: Byron Quisenberry | I28: Byron Quisenberry | J28: Pepper Martin | K28: United States | N28: Calendar International Pictures | O28: 82 | P28: =_xlfn.XLOOKUP(D28,Consumer_Price_Index!A:A,Consumer_Price_Index!B:B) -> 90.9 | Q28: =IF(ISNUMBER(M28), M28*(Consumer_Price_Index!$B$45/(_xlfn.XLOOKUP('Working Data'!D200,Consumer_Price_Index!A:A,Consumer_Price_Index!B:B))), "Missing") -> Missing | R28: =IF(AND(ISNUMBER(L28), L28>0, ISNUMBER(M28), M28>0), "Yes", "No") -> No
A29: Steel | B29: PG-13 | C29: Action | D29: 1997 | E29: August 15, 1997 (United States) | F29: 2.9 | G29: 12000 | H29: Kenneth Johnson | I29: Louise Simonson | J29: Shaquille O'Neal | K29: United States | L29: 16000000 | M29: 1710972 | N29: DC Entertainment | O29: 97 | P29: =_xlfn.XLOOKUP(D29,Consumer_Price_Index!A:A,Consumer_Price_Index!B:B) -> 160.5 | Q29: =IF(ISNUMBER(M29), M29*(Consumer_Price_Index!$B$45/(_xlfn.XLOOKUP('Working Data'!D3151,Consumer_Price_Index!A:A,Consumer_Price_Index!B:B))), "Missing") -> 3517767.7 | R29: =IF(AND(ISNUMBER(L29), L29>0, ISNUMBER(M29), M29>0), "Yes", "No") -> Yes
A30: 3 Ninjas: High Noon at Mega Mountain | B30: PG | C30: Action | D30: 1998 | E30: June 18, 1998 (Australia) | F30: 3 | G30: 11000 | H30: Sean McNamara | I30: Sean McNamara | J30: Loni Anderson | K30: United States | M30: 375805 | N30: Leeds/Ben-Ami Productions | O30: 93 | P30: =_xlfn.XLOOKUP(D30,Consumer_Price_Index!A:A,Consumer_Price_Index!B:B) -> 163 | Q30: =IF(ISNUMBER(M30), M30*(Consumer_Price_Index!$B$45/(_xlfn.XLOOKUP('Working Data'!D3401,Consumer_Price_Index!A:A,Consumer_Price_Index!B:B))), "Missing") -> 1102096.1 | R30: =IF(AND(ISNUMBER(L30), L30>0, ISNUMBER(M30), M30>0), "Yes", "No") -> No
A31: Bolero | B31: R | C31: Comedy | D31: 1984 | E31: August 31, 1984 (United States) | F31: 3 | G31: 5100 | H31: John Derek | I31: John Derek | J31: Bo Derek | K31: United States | L31: 7000000 | M31: 8914881 | N31: City Films | O31: 105 | P31: =_xlfn.XLOOKUP(D31,Consumer_Price_Index!A:A,Consumer_Price_Index!B:B) -> 103.9 | Q31: =IF(ISNUMBER(M31), M31*(Consumer_Price_Index!$B$45/(_xlfn.XLOOKUP('Working Data'!D530,Consumer_Price_Index!A:A,Consumer_Price_Index!B:B))), "Missing") -> 20783200 | R31: =IF(AND(ISNUMBER(L31), L31>0, ISNUMBER(M31), M31>0), "Yes", "No") -> Yes
A32: El Coyote | B32: R | C32: Action | D32: 2019 | E32: October 4, 2019 (United States) | F32: 3 | G32: 122 | H32: Jeffrey Nicholson | I32: Jeffrey Nicholson | J32: Michael Saquella | K32: United States | M32: 1101470 | N32: Cactus Blue Entertainment | O32: 93 | P32: =_xlfn.XLOOKUP(D32,Consumer_Price_Index!A:A,Consumer_Price_Index!B:B) -> 255.7 | Q32: =IF(ISNUMBER(M32), M32*(Consumer_Price_Index!$B$45/(_xlfn.XLOOKUP('Working Data'!D7642,Consumer_Price_Index!A:A,Consumer_Price_Index!B:B))), "Missing") -> 1664771.4 | R32: =IF(AND(ISNUMBER(L32), L32>0, ISNUMBER(M32), M32>0), "Yes", "No") -> No
A33: Jaws: the Revenge | B33: PG-13 | C33: Adventure | D33: 1987 | E33: July 17, 1987 (United States) | F33: 3 | G33: 42000 | H33: Joseph Sargent | I33: Peter Benchley | J33: Lorraine Gary | K33: United States | L33: 23000000 | M33: 51881013 | N33: Universal Pictures | O33: 89 | P33: =_xlfn.XLOOKUP(D33,Consumer_Price_Index!A:A,Consumer_Price_Index!B:B) -> 113.6 | Q33: =IF(ISNUMBER(M33), M33*(Consumer_Price_Index!$B$45/(_xlfn.XLOOKUP('Working Data'!D1069,Consumer_Price_Index!A:A,Consumer_Price_Index!B:B))), "Missing") -> 80942881 | R33: =IF(AND(ISNUMBER(L33), L33>0, ISNUMBER(M33), M33>0), "Yes", "No") -> Yes
A34: Kazaam | B34: PG | C34: Comedy | D34: 1996 | E34: July 17, 1996 (United States) | F34: 3 | G34: 23000 | H34: Paul Michael Glaser | I34: Paul Michael Glaser | J34: Shaquille O'Neal | K34: United States | L34: 20000000 | M34: 18937262 | N34: Interscope Communications | O34: 93 | P34: =_xlfn.XLOOKUP(D34,Consumer_Price_Index!A:A,Consumer_Price_Index!B:B) -> 156.9 | Q34: =IF(ISNUMBER(M34), M34*(Consumer_Price_Index!$B$45/(_xlfn.XLOOKUP('Working Data'!D2927,Consumer_Price_Index!A:A,Consumer_Price_Index!B:B))), "Missing") -> 53626243 | R34: =IF(AND(ISNUMBER(L34), L34>0, ISNUMBER(M34), M34>0), "Yes", "No") -> Yes
A35: The Lonely Lady | B35: R | C35: Drama | D35: 1983 | E35: September 30, 1983 (United States) | F35: 3 | G35: 938 | H35: Peter Sasdy | I35: Harold Robbins | J35: Pia Zadora | K35: United States | L35: 5000000 | M35: 1223200 | N35: Harold Robbins International Company | O35: 92 | P35: =_xlfn.XLOOKUP(D35,Consumer_Price_Index!A:A,Consumer_Price_Index!B:B) -> 99.6 | Q35: =IF(ISNUMBER(M35), M35*(Consumer_Price_Index!$B$45/(_xlfn.XLOOKUP('Working Data'!D429,Consumer_Price_Index!A:A,Consumer_Price_Index!B:B))), "Missing") -> 1457602.8 | R35: =IF(AND(ISNUMBER(L35), L35>0, ISNUMBER(M35), M35>0), "Yes", "No") -> Yes
A36: Bratz | B36: PG | C36: Comedy | D36: 2007 | E36: August 3, 2007 (United States) | F36: 3.1 | G36: 18000 | H36: Sean McNamara | I36: Susan Estelle Jansen | J36: Skyler Shaye | K36: United States | L36: 20000000 | M36: 26013153 | N36: Avi Arad & Associates | O36: 110 | P36: =_xlfn.XLOOKUP(D36,Consumer_Price_Index!A:A,Consumer_Price_Index!B:B) -> 207.3 | Q36: =IF(ISNUMBER(M36), M36*(Consumer_Price_Index!$B$45/(_xlfn.XLOOKUP('Working Data'!D5170,Consumer_Price_Index!A:A,Consumer_Price_Index!B:B))), "Missing") -> 87197005 | R36: =IF(AND(ISNUMBER(L36), L36>0, ISNUMBER(M36), M36>0), "Yes", "No") -> Yes
A37: Left Behind | B37: PG-13 | C37: Action | D37: 2014 | E37: October 3, 2014 (United States) | F37: 3.1 | G37: 38000 | H37: Vic Armstrong | I37: Paul Lalonde | J37: Nicolas Cage | K37: United States | L37: 16000000 | M37: 27405896 | N37: Stoney Lake Entertainment | O37: 110 | P37: =_xlfn.XLOOKUP(D37,Consumer_Price_Index!A:A,Consumer_Price_Index!B:B) -> 236.7 | Q37: =IF(ISNUMBER(M37), M37*(Consumer_Price_Index!$B$45/(_xlfn.XLOOKUP('Working Data'!D6595,Consumer_Price_Index!A:A,Consumer_Price_Index!B:B))), "Missing") -> 83841130 | R37: =IF(AND(ISNUMBER(L37), L37>0, ISNUMBER(M37), M37>0), "Yes", "No") -> Yes
A38: Martians Go Home | B38: PG-13 | C38: Comedy | D38: 1989 | E38: April 20, 1990 (United States) | F38: 3.1 | G38: 666 | H38: David Odell | I38: Fredric Brown | J38: Randy Quaid | K38: United States | M38: 129778 | N38: Edward R. Pressman Productions | O38: 89 | P38: =_xlfn.XLOOKUP(D38,Consumer_Price_Index!A:A,Consumer_Price_Index!B:B) -> 124 | Q38: =IF(ISNUMBER(M38), M38*(Consumer_Price_Index!$B$45/(_xlfn.XLOOKUP('Working Data'!D1634,Consumer_Price_Index!A:A,Consumer_Price_Index!B:B))), "Missing") -> 166849.61 | R38: =IF(AND(ISNUMBER(L38), L38>0, ISNUMBER(M38), M38>0), "Yes", "No") -> No
A39: More to Life | C39: Drama | D39: 2020 | E39: October 23, 2020 (United States) | F39: 3.1 | G39: 18 | H39: Joseph Ebanks | I39: Joseph Ebanks | J39: Shannon Bond | K39: United States | L39: 7000 | O39: 90 | P39: =_xlfn.XLOOKUP(D39,Consumer_Price_Index!A:A,Consumer_Price_Index!B:B) -> 258.8 | Q39: =IF(ISNUMBER(M39), M39*(Consumer_Price_Index!$B$45/(_xlfn.XLOOKUP('Working Data'!D7665,Consumer_Price_Index!A:A,Consumer_Price_Index!B:B))), "Missing") -> Missing | R39: =IF(AND(ISNUMBER(L39), L39>0, ISNUMBER(M39), M39>0), "Yes", "No") -> No
A40: Rollerball | B40: PG-13 | C40: Action | D40: 2002 | E40: February 8, 2002 (United States) | F40: 3.1 | G40: 26000 | H40: John McTiernan | I40: William Harrison | J40: Chris Klein | K40: United States | L40: 70000000 | M40: 25852764 | N40: Atlas Entertainment | O40: 98 | P40: =_xlfn.XLOOKUP(D40,Consumer_Price_Index!A:A,Consumer_Price_Index!B:B) -> 179.9 | Q40: =IF(ISNUMBER(M40), M40*(Consumer_Price_Index!$B$45/(_xlfn.XLOOKUP('Working Data'!D4168,Consumer_Price_Index!A:A,Consumer_Price_Index!B:B))), "Missing") -> 33808314 | R40: =IF(AND(ISNUMBER(L40), L40>0, ISNUMBER(M40), M40>0), "Yes", "No") -> Yes
...

Sheet pivottable_genre
A1: Valid movie | B1: Yes
A3: Row Labels | B3: Average of Gross relative to budget
A4: Action | B4: 2.8727601
A5: Adventure | B5: 2.8997264
A6: Animation | B6: 3.6833103
A7: Biography | B7: 2.4134502
A8: Comedy | B8: 2.5948028
A9: Crime | B9: 2.218839
A10: Drama | B10: 2.5972081
A11: Family | B11: 10.143436
A12: Fantasy | B12: 2.3279211
A13: Horror | B13: 4.2219441
A14: Mystery | B14: 3.6982681
A15: Romance | B15: 1.3966465
... A19: Grand Total | B19: 2.8661203

Sheet pivottable_rating
A1: Valid movie | B1: Yes
A3: Row Labels | B3: Average of Gross relative to budget
A4: G | B4: 3.5504056
A5: NC-17 | B5: 1.5843237
A6: PG | B6: 3.1217287
A7: PG-13 | B7: 3.0216556
A8: R | B8: 2.40136
A9: Grand Total | B9: 2.864802

Sheet pivottable_score
A2: Valid movie | B2: Yes
A4: Row Labels | B4: Average of Gross relative to budget
A5: 8-9 | B5: 5.9867212
A6: 9-10 | B6: 4.9275759
A7: 7-8 | B7: 3.7524221
A8: 6-7 | B8: 2.5834207
A9: 5-6 | B9: 1.9381276
A10: 4-5 | B10: 1.7977551
A11: 3-4 | B11: 1.2591825
A12: 1-2 | B12: 1.1066367
A13: 2-3 | B13: 0.93170756
A14: Grand Total | B14: 2.8661203

Sheet Inflation_adjusted_pivot
A3: Row Labels | B3: Sum of Gross Revenue in 2023 Dollars
A4: 1980 | B4: 4.3784903e+09
A5: 1981 | B5: 5.155092e+09
A6: 1982 | B6: 6.2978915e+09
A7: 1983 | B7: 5.4801162e+09
A8: 1984 | B8: 8.1056768e+09
A9: 1985 | B9: 7.7307778e+09
A10: 1986 | B10: 6.7159311e+09
A11: 1987 | B11: 8.3863461e+09
A12: 1988 | B12: 9.9325604e+09
A13: 1989 | B13: 1.1183829e+10
A14: 1990 | B14: 1.2734153e+10
A15: 1991 | B15: 1.1184934e+10
... A44: 2020 | B44: 5.3195422e+09
A45: Grand Total | B45: 1.1026885e+12

Sheet Pivot_Chart
A3: Row Labels | B3: Sum of gross
A4: 1980 | B4: 2483666964
A5: 1981 | B5: 2520064889
A6: 1982 | B6: 3187580517
A7: 1983 | B7: 2750004626
A8: 1984 | B8: 3533092196
A9: 1985 | B9: 3691509283
A10: 1986 | B10: 3647511836
A11: 1987 | B11: 4033434255
A12: 1988 | B12: 4840385631
A13: 1989 | B13: 6087250779
A14: 1990 | B14: 6804235860
A15: 1991 | B15: 6254770668
... A44: 2020 | B44: 2848298792
A45: Grand Total | B45: 587105546272

Sheet Consumer_Price_Index
A1: Year | B1: Annual Average CPI (-U) | C1: Annual Percent Change (rate of inflation)
A2: 1980 | B2: 82.4 | C2: 0.135
A3: 1981 | B3: 90.9 | C3: 0.103
A4: 1982 | B4: 96.5 | C4: 0.061
A5: 1983 | B5: 99.6 | C5: 0.032
A6: 1984 | B6: 103.9 | C6: 0.043
A7: 1985 | B7: 107.6 | C7: 0.035
A8: 1986 | B8: 109.6 | C8: 0.019
A9: 1987 | B9: 113.6 | C9: 0.037
A10: 1988 | B10: 118.3 | C10: 0.041
A11: 1989 | B11: 124 | C11: 0.048
A12: 1990 | B12: 130.7 | C12: 0.054
A13: 1991 | B13: 136.2 | C13: 0.042
... A47: 2025 | B47: 322.3 | C47: 0.027
